<?xml version="0.0" ?>
<robot name="morpheus">
  <link name="spine">
    <inertial>
      <origin rpy="0 0 0" xyz="0 0 0"/>
       <mass value=".01"/>
       <inertia ixx="0" ixy="0" ixz="0" iyy="0" iyz="0" izz="0"/>
    </inertial>
    <visual>
      <origin rpy="0 0 0" xyz="0 0 0"/>
      <geometry>
				<box size="0.05 0.05 1.8"/>
      </geometry>
       <material name="black">
        <color rgba="0.01 0.01 0.01 1"/>
      </material>
    </visual>
    <collision>
      <origin rpy="0 0 0" xyz="0 0 0"/>
      <geometry>
	 	   <box size="0.05 0.05 1.8"/>
      </geometry>
    </collision>
  </link>

  <link name="arm1">
    <inertial>
      <origin rpy="0 0 0" xyz="0 0 0"/>
       <mass value=".01"/>
       <inertia ixx="0" ixy="0" ixz="0" iyy="0" iyz="0" izz="0"/>
    </inertial>
    <visual>
      <origin rpy="0 1.57 0" xyz="0.15 0 -0.5"/>
      <geometry>
        <box size="0.075 0.075 0.3"/>
      </geometry>
       <material name="black">
        <color rgba="0.01 0.01 0.01 1"/>
      </material>
    </visual>
    <collision>
      <origin rpy="0 1.57 0" xyz="0.15 0 -0.5"/>
      <geometry>
       <box size="0.05 0.05 0.3"/>
      </geometry>
    </collision>
  </link>

  <joint name="spine_to_arm1" type="prismatic">
    <parent link="spine"/>
    <child link="arm1"/>
    <origin rpy="0 0 0" xyz="0 0 0"/>
    <axis xyz="0 0 1"/>
    <limit lower="0.0" upper="1.3" effort="10" velocity="0.25"/>
  </joint>

  <link name="head">
    <inertial>
      <origin rpy="0 0 0" xyz="0 0 0"/>
       <mass value=".01"/>
       <inertia ixx="0" ixy="0" ixz="0" iyy="0" iyz="0" izz="0"/>
    </inertial>
    <visual>
      <origin rpy="0 1.57 0" xyz="0.04 0 0.9"/>
      <geometry>
        <box size="0.05 0.05 0.15"/>
      </geometry>
       <material name="black">
        <color rgba="0.01 0.01 0.01 1"/>
      </material>
    </visual>
    <collision>
      <origin rpy="0 1.57 0" xyz="0.04 0 0.9"/>
      <geometry>
       <box size="0.05 0.05 0.15"/>
      </geometry>
    </collision>
  </link>

  <joint name="spine_to_head" type="fixed">
    <parent link="spine"/>
    <child link="head"/>
  </joint>


  <link name="arm2">
    <inertial>
      <origin rpy="0 0 0" xyz="0 0 0"/>
       <mass value=".01"/>
       <inertia ixx="0" ixy="0" ixz="0" iyy="0" iyz="0" izz="0"/>
    </inertial>
    <visual>
      <origin rpy="0 1.57 0" xyz="0.15 0 -0.5"/>
      <geometry>
        <box size="0.07 0.07 0.3"/>
      </geometry>
       <material name="grey1">
        <color rgba="0.23 0.22 0.21 1"/>
        </material>
    </visual>
    <collision>
      <origin rpy="0 1.57 0" xyz="0.15 0 -0.5"/>
      <geometry>
       <box size="0.07 0.07 0.3"/>
      </geometry>
    </collision>
  </link>

  <joint name="arm1_to_arm2" type="prismatic">
    <parent link="arm1"/>
    <child link="arm2"/>
    <origin rpy="0 0 0" xyz="0 0 0"/>
    <axis xyz="1 0 0"/>
    <limit lower="0.0" upper="0.25" effort="10" velocity="0.25"/>
  </joint>

  <link name="arm3">
    <inertial>
      <origin rpy="0 0 0" xyz="0 0 0"/>
       <mass value=".01"/>
       <inertia ixx="0" ixy="0" ixz="0" iyy="0" iyz="0" izz="0"/>
    </inertial>
    <visual>
      <origin rpy="0 1.57 0" xyz="0.15 0 -0.5"/>
      <geometry>
        <box size="0.06 0.06 0.3"/>
      </geometry>
       <material name="grey2">
        <color rgba="0.32 0.31 0.31 1"/>
      </material>
    </visual>
    <collision>
      <origin rpy="0 1.57 0" xyz="0.15 0 -0.5"/>
      <geometry>
       <box size="0.06 0.06 0.3"/>
      </geometry>
    </collision>
  </link>

  <joint name="arm2_to_arm3" type="prismatic">
    <parent link="arm2"/>
    <child link="arm3"/>
    <origin rpy="0 0 0" xyz="0 0 0"/>
    <axis xyz="1 0 0"/>
    <limit lower="0.0" upper="0.25" effort="10" velocity="0.25"/>
  </joint>

  <link name="arm4">
    <inertial>
      <origin rpy="0 0 0" xyz="0 0 0"/>
       <mass value=".01"/>
       <inertia ixx="0" ixy="0" ixz="0" iyy="0" iyz="0" izz="0"/>
    </inertial>
    <visual>
      <origin rpy="0 1.57 0" xyz="0.15 0 -0.5"/>
      <geometry>
        <box size="0.05 0.05 0.3"/>
      </geometry>
       <material name="grey3">
        <color rgba="0.49 0.48 0.48 1"/>
      </material>
    </visual>
    <collision>
      <origin rpy="0 1.57 0" xyz="0.15 0 -0.5"/>
      <geometry>
       <box size="0.05 0.05 0.3"/>
      </geometry>
    </collision>
  </link>

  <joint name="arm3_to_arm4" type="prismatic">
    <parent link="arm3"/>
    <child link="arm4"/>
    <origin rpy="0 0 0" xyz="0 0 0"/>
    <axis xyz="1 0 0"/>
    <limit lower="0.0" upper="0.25" effort="10" velocity="0.25"/>
  </joint>

  <link name="arm5">
    <inertial>
      <origin rpy="0 0 0" xyz="0 0 0"/>
       <mass value=".01"/>
       <inertia ixx="0" ixy="0" ixz="0" iyy="0" iyz="0" izz="0"/>
    </inertial>
    <visual>
      <origin rpy="0 1.57 0" xyz="0.15 0 -0.5"/>
      <geometry>
        <box size="0.04 0.04 0.3"/>
      </geometry>
       <material name="grey4">
        <color rgba="0.74 0.73 0.73 1"/>
      </material>
    </visual>
    <collision>
      <origin rpy="0 1.57 0" xyz="0.15 0 -0.5"/>
      <geometry>
       <box size="0.04 0.04 0.3"/>
      </geometry>
    </collision>
  </link>

  <joint name="arm4_to_arm5" type="prismatic">
    <parent link="arm4"/>
    <child link="arm5"/>
    <origin rpy="0 0 0" xyz="0 0 0"/>
    <axis xyz="1 0 0"/>
    <limit lower="0.0" upper="0.25" effort="10" velocity="0.25"/>
  </joint>

  <link name="wrist">
    <inertial>
      <origin rpy="0 0 0" xyz="0 0 0.02"/>
       <mass value=".01"/>
       <inertia ixx="0" ixy="0" ixz="0" iyy="0" iyz="0" izz="0"/>
    </inertial>
    <visual>
      <origin rpy="0 0 0" xyz="0.28 0 -0.54"/>
      <geometry>
        <box size="0.04 0.04 0.04"/>
      </geometry>
       <material name="red">
        <color rgba="1 0 0 1"/>
      </material>
    </visual>
    <collision>
      <origin rpy="0 0 0" xyz="0.28 0 -0.54"/>
      <geometry>
       <box size="0.07 0.07 0.07"/>
      </geometry>
    </collision>
  </link>

  <joint name="arm5_to_wrist" type="revolute">
    <parent link="arm5"/>
    <child link="wrist"/>
    <!-- <origin rpy="0 0 0" xyz="0 0 0"/> -->
    <axis xyz="0 0 1"/>
    <limit lower="-0.25" upper="0.25" effort="1" velocity="10"/>
  </joint>

  <link name="gripper_base">
    <inertial>
      <origin rpy="0 0 0" xyz="0 0 0"/>
       <mass value=".01"/>
       <inertia ixx="0" ixy="0" ixz="0" iyy="0" iyz="0" izz="0"/>
    </inertial>
    <visual>
      <origin rpy="0 0.86 0" xyz="0.29 0 -0.56"/>
      <geometry>
        <box size="0.01 0.2 0.03"/>
      </geometry>
       <material name="grey3"/>
    </visual>
    <collision>
      <origin rpy="0 0.86 0" xyz="0.29 0 -0.56"/>
      <geometry>
       <box size="0.01 0.2 0.03"/>
      </geometry>
    </collision>
  </link>

  <joint name="wrist_to_gripper_base" type="fixed">
    <parent link="wrist"/>
    <child link="gripper_base"/>
  </joint>

<link name="left_gripper">
    <inertial>
      <origin rpy="0 0 0" xyz="0 0 0"/>
       <mass value=".01"/>
       <inertia ixx="0" ixy="0" ixz="0" iyy="0" iyz="0" izz="0"/>
    </inertial>
    <visual>
      <origin rpy="-0.86 0 -1.57" xyz="0.32 0.06 -0.613"/>
      <geometry>
        <mesh filename="left_gripper.stl" scale="1 1 1"/>
      </geometry>
       <material name="black"/>
    </visual>
    <collision>
      <origin rpy="-0.86 0 -1.57" xyz="0.32 0.06 -0.613"/>
      <geometry>
       <mesh filename="left_gripper.stl" scale="1 1 1"/>
      </geometry>
    </collision>
  </link>

  <joint name="gripper_base_to_left_gripper" type="fixed">
    <parent link="gripper_base"/>
    <child link="left_gripper"/>
  </joint>

<link name="right_gripper">
    <inertial>
      <origin rpy="0 0 0" xyz="0 0 0"/>
       <mass value=".01"/>
       <inertia ixx="0" ixy="0" ixz="0" iyy="0" iyz="0" izz="0"/>
    </inertial>
    <visual>
      <origin rpy="-0.86 0 -1.57" xyz="0.32 -0.06 -0.613"/>
      <geometry>
        <mesh filename="right_gripper.stl" scale="1 1 1"/>
      </geometry>
       <material name="black"/>
    </visual>
    <collision>
      <origin rpy="-0.86 0 -1.57" xyz="0.32 -0.06 -0.613"/>
      <geometry>
       <mesh filename="right_gripper.stl" scale="1 1 1"/>
      </geometry>
    </collision>
  </link>

  <joint name="gripper_base_to_right_gripper" type="fixed">
    <parent link="gripper_base"/>
    <child link="right_gripper"/>
  </joint>




</robot>

