<?xml version="1.0" ?>
<robot name="husky_robot" xmlns:xacro="http://ros.org/wiki/xacro">
  <!-- Included URDF/XACRO Files -->
  <material name="Black">
    <color rgba="0.1 0.1 0.1 1.0"/>
  </material>
  <material name="Blue">
    <color rgba="0.0 0.0 0.8 1.0"/>
  </material>
  <material name="Green">
    <color rgba="0.0 0.8 0.0 1.0"/>
  </material>
  <material name="Grey">
    <color rgba="0.7 0.7 0.7 1.0"/>
  </material>
  <material name="DarkGrey">
    <color rgba="0.3 0.3 0.3 1.0"/>
  </material>
  <material name="Red">
    <color rgba="0.8 0.0 0.0 1.0"/>
  </material>
  <material name="White">
    <color rgba="1.0 1.0 1.0 1.0"/>
  </material>
  <material name="Yellow">
    <color rgba="0.8 0.8 0.0 1.0"/>
  </material>
  <material name="Brown">
    <color rgba="0.52 0.24 0.02 1.0"/>
  </material>
  <material name="Purple">
    <color rgba="0.37 0.02 0.52 1.0"/>
  </material>
  <!-- Base Size -->
  <!-- Wheel Mounting Positions -->
  <!-- Wheel Properties -->
  <!-- Base link is on the ground under the robot -->
  <link name="base_footprint"/>
  <gazebo reference="base_footprint">
    <material>Gazebo/DarkGrey</material>
  </gazebo>
  <joint name="chassis_joint" type="fixed">
    <origin rpy="0 0 0" xyz="0 0 0.14493"/>
    <parent link="base_footprint"/>
    <child link="base_link"/>
  </joint>
  <!-- Chassis link is the center of the robot's bottom plate -->
  <link name="base_link">
    <visual>
      <origin rpy="0 0 0" xyz="0 0 0"/>
      <geometry>
        <mesh filename="meshes/base_link.stl"/>
      </geometry>
      <material name="Black"/>
    </visual>
    <collision>
      <origin rpy="0 0 0" xyz="0 0 0.12498"/>
      <geometry>
        <!-- Make collision box slightly bigger in x and z directions. -->
        <box size="1.0074 0.5709 0.2675"/>
      </geometry>
    </collision>
    <inertial>
      <mass value="33.455"/>
      <origin xyz="-0.08748 -0.00085 0.09947"/>
      <inertia ixx="0.6022" ixy="-0.02364" ixz="-0.1197" iyy="1.7386" iyz="-0.001544" izz="2.0296"/>
    </inertial>
  </link>
  <gazebo reference="base_link">
    </gazebo>
  <!-- IMU Link is the standard mounting position for the UM6 IMU.-->
  <!-- Can be modified with environment variables in /etc/ros/setup.bash -->
  <link name="imu_link"/>
  <joint name="imu_joint" type="fixed">
    <origin rpy="$(optenv HUSKY_IMU_RPY 0 -1.5708 3.1416)" xyz="$(optenv HUSKY_IMU_XYZ 0.19 0 0.149)"/>
    <parent link="base_link"/>
    <child link="imu_link"/>
  </joint>
  <gazebo reference="imu_link">
    </gazebo>
  <!-- Husky wheel macros -->
  <link name="front_left_wheel_link">
  	<contact>
      <lateral_friction value="1.0"/>
      <rolling_friction value="0.0"/>
      <stiffness value="30000"/>
      <damping value="1000"/>
    </contact>
    
    <inertial>
      <mass value="2.637"/>
      <origin xyz="0 0 0"/>
      <inertia ixx="0.02467" ixy="0" ixz="0" iyy="0.02467" iyz="0" izz="0.04411"/>
    </inertial>
    <visual>
      <origin rpy="0 0 0" xyz="0 0 0"/>
      <geometry>
        <mesh filename="meshes/wheel.stl"/>
      </geometry>
      <material name="DarkGrey"/>
    </visual>
    <collision>
      <origin rpy="1.570795 0 0" xyz="0 0 0"/>
      <geometry>
        <cylinder length="0.1143" radius="0.17775"/>
      </geometry>
    </collision>
  </link>
  <gazebo reference="front_left_wheel_link">
    <mu1 value="1.0"/>
    <mu2 value="1.0"/>
    <kp value="10000000.0"/>
    <kd value="1.0"/>
    <fdir1 value="1 0 0"/>
    <material>Gazebo/Grey</material>
    <turnGravityOff>false</turnGravityOff>
  </gazebo>
  <joint name="front_left_wheel" type="continuous">
    <parent link="base_link"/>
    <child link="front_left_wheel_link"/>
    <origin rpy="0 0 0" xyz="0.256 0.2854 0.03282"/>
    <axis rpy="0 0 0" xyz="0 1 0"/>
  </joint>
  <transmission name="front_left_wheel_trans" type="SimpleTransmission">
    <type>transmission_interface/SimpleTransmission</type>
    <actuator name="front_left_wheel_motor">
      <mechanicalReduction>1</mechanicalReduction>
    </actuator>
    <joint name="front_left_wheel">
      <hardwareInterface>VelocityJointInterface</hardwareInterface>
    </joint>
  </transmission>
  <link name="front_right_wheel_link">
    <contact>
      <lateral_friction value="1.0"/>
      <rolling_friction value="0.0"/>
      <stiffness value="30000"/>
      <damping value="1000"/>
    </contact>
    
    <inertial>
      <mass value="2.637"/>
      <origin xyz="0 0 0"/>
      <inertia ixx="0.02467" ixy="0" ixz="0" iyy="0.02467" iyz="0" izz="0.04411"/>
    </inertial>
    <visual>
      <origin rpy="0 0 0" xyz="0 0 0"/>
      <geometry>
        <mesh filename="meshes/wheel.stl"/>
      </geometry>
      <material name="DarkGrey"/>
    </visual>
    <collision>
      <origin rpy="1.570795 0 0" xyz="0 0 0"/>
      <geometry>
        <cylinder length="0.1143" radius="0.17775"/>
      </geometry>
    </collision>
  </link>
  <gazebo reference="front_right_wheel_link">
    <mu1 value="1.0"/>
    <mu2 value="1.0"/>
    <kp value="10000000.0"/>
    <kd value="1.0"/>
    <fdir1 value="1 0 0"/>
    <material>Gazebo/Grey</material>
    <turnGravityOff>false</turnGravityOff>
  </gazebo>
  <joint name="front_right_wheel" type="continuous">
    <parent link="base_link"/>
    <child link="front_right_wheel_link"/>
    <origin rpy="0 0 0" xyz="0.256 -0.2854 0.03282"/>
    <axis rpy="0 0 0" xyz="0 1 0"/>
  </joint>
  <transmission name="front_right_wheel_trans" type="SimpleTransmission">
    <type>transmission_interface/SimpleTransmission</type>
    <actuator name="front_right_wheel_motor">
      <mechanicalReduction>1</mechanicalReduction>
    </actuator>
    <joint name="front_right_wheel">
      <hardwareInterface>VelocityJointInterface</hardwareInterface>
    </joint>
  </transmission>
  <link name="rear_left_wheel_link">
    <contact>
      <lateral_friction value="1.0"/>
      <rolling_friction value="0.0"/>
      <stiffness value="30000"/>
      <damping value="1000"/>
    </contact>
    
    <inertial>
      <mass value="2.637"/>
      <origin xyz="0 0 0"/>
      <inertia ixx="0.02467" ixy="0" ixz="0" iyy="0.02467" iyz="0" izz="0.04411"/>
    </inertial>
    <visual>
      <origin rpy="0 0 0" xyz="0 0 0"/>
      <geometry>
        <mesh filename="meshes/wheel.stl"/>
      </geometry>
      <material name="DarkGrey"/>
    </visual>
    <collision>
      <origin rpy="1.570795 0 0" xyz="0 0 0"/>
      <geometry>
        <cylinder length="0.1143" radius="0.17775"/>
      </geometry>
    </collision>
  </link>
  <gazebo reference="rear_left_wheel_link">
    <mu1 value="1.0"/>
    <mu2 value="1.0"/>
    <kp value="10000000.0"/>
    <kd value="1.0"/>
    <fdir1 value="1 0 0"/>
    <material>Gazebo/Grey</material>
    <turnGravityOff>false</turnGravityOff>
  </gazebo>
  <joint name="rear_left_wheel" type="continuous">
    <parent link="base_link"/>
    <child link="rear_left_wheel_link"/>
    <origin rpy="0 0 0" xyz="-0.256 0.2854 0.03282"/>
    <axis rpy="0 0 0" xyz="0 1 0"/>
  </joint>
  <transmission name="rear_left_wheel_trans" type="SimpleTransmission">
    <type>transmission_interface/SimpleTransmission</type>
    <actuator name="rear_left_wheel_motor">
      <mechanicalReduction>1</mechanicalReduction>
    </actuator>
    <joint name="rear_left_wheel">
      <hardwareInterface>VelocityJointInterface</hardwareInterface>
    </joint>
  </transmission>
  <link name="rear_right_wheel_link">
    <contact>
      <lateral_friction value="1.0"/>
      <rolling_friction value="0.0"/>
      <stiffness value="30000"/>
      <damping value="1000"/>
    </contact>
    
    <inertial>
      <mass value="2.637"/>
      <origin xyz="0 0 0"/>
      <inertia ixx="0.02467" ixy="0" ixz="0" iyy="0.02467" iyz="0" izz="0.04411"/>
    </inertial>
    <visual>
      <origin rpy="0 0 0" xyz="0 0 0"/>
      <geometry>
        <mesh filename="meshes/wheel.stl"/>
      </geometry>
      <material name="DarkGrey"/>
    </visual>
    <collision>
      <origin rpy="1.570795 0 0" xyz="0 0 0"/>
      <geometry>
        <cylinder length="0.1143" radius="0.17775"/>
      </geometry>
    </collision>
  </link>
  <gazebo reference="rear_right_wheel_link">
    <mu1 value="1.0"/>
    <mu2 value="1.0"/>
    <kp value="10000000.0"/>
    <kd value="1.0"/>
    <fdir1 value="1 0 0"/>
    <material>Gazebo/Grey</material>
    <turnGravityOff>false</turnGravityOff>
  </gazebo>
  <joint name="rear_right_wheel" type="continuous">
    <parent link="base_link"/>
    <child link="rear_right_wheel_link"/>
    <origin rpy="0 0 0" xyz="-0.256 -0.2854 0.03282"/>
    <axis rpy="0 0 0" xyz="0 1 0"/>
  </joint>
  <transmission name="rear_right_wheel_trans" type="SimpleTransmission">
    <type>transmission_interface/SimpleTransmission</type>
    <actuator name="rear_right_wheel_motor">
      <mechanicalReduction>1</mechanicalReduction>
    </actuator>
    <joint name="rear_right_wheel">
      <hardwareInterface>VelocityJointInterface</hardwareInterface>
    </joint>
  </transmission>
  <link name="top_plate_link">
    <visual>
      <origin rpy="0 0 0" xyz="0 0 0"/>
      <geometry>
        <mesh filename="meshes/top_plate.stl"/>
      </geometry>
      <material name="Yellow"/>
    </visual>
  </link>
  <joint name="top_plate" type="fixed">
    <parent link="base_link"/>
    <child link="top_plate_link"/>
  </joint>
  <gazebo reference="top_plate_link">
    <material>Gazebo/Yellow</material>
  </gazebo>

  <link name="platform_link">
    <visual>
      <origin rpy="0 0 0" xyz="0 0 0.2"/>
      <geometry>
        <!-- <mesh filename="meshes/platform.stl"/> -->
        <box size="0.3 0.3 0.1"/>
      </geometry>
      <material name="Black"/>
    </visual>
    <collision>
      <origin rpy="0 0 0" xyz="0 0 0.3"/>
      <geometry>
        <box size="0.3 0.3 0.1"/>
      </geometry>
      <material name="Black"/>
    </collision>

  </link>
  <joint name="platform" type="fixed">
    <parent link="top_plate_link"/>
    <child link="platform_link"/>
  </joint>
  <gazebo reference="platform_link">
    <material>Gazebo/Black</material>
  </gazebo>

  <link name="user_rail_link">
    <visual>
      <geometry>
        <mesh filename="meshes/user_rail.stl"/>
      </geometry>
      <material name="DarkGrey"/>
    </visual>
  </link>
  <joint name="user_rail" type="fixed">
    <origin rpy="0 0 0" xyz="0.272 0 0.245"/>
    <parent link="base_link"/>
    <child link="user_rail_link"/>
  </joint>
  <gazebo reference="user_rail_link">
    <material>Gazebo/DarkGrey</material>
  </gazebo>
  <link name="front_bumper_link">
    <visual>
      <geometry>
        <mesh filename="meshes/bumper.stl"/>
      </geometry>
      <material name="DarkGrey"/>
    </visual>
  </link>
  <joint name="front_bumper" type="fixed">
    <origin rpy="0 0 0" xyz="0.48 0 0.091"/>
    <parent link="base_link"/>
    <child link="front_bumper_link"/>
  </joint>
  <gazebo reference="front_bumper_link">
    <material>Gazebo/DarkGrey</material>
  </gazebo>
  <link name="rear_bumper_link">
    <visual>
      <geometry>
        <mesh filename="meshes/bumper.stl"/>
      </geometry>
      <material name="DarkGrey"/>
    </visual>
  </link>
  <joint name="rear_bumper" type="fixed">
    <origin rpy="0 0 3.14159" xyz="-0.48 0 0.091"/>
    <parent link="base_link"/>
    <child link="rear_bumper_link"/>
  </joint>
  <gazebo reference="rear_bumper_link">
    <material>Gazebo/DarkGrey</material>
  </gazebo>


  <!-- MORPH -->
  <link name="spine">
    <inertial>
      <origin rpy="0 0 0" xyz="0 0 0"/>
       <mass value=".01"/>
       <inertia ixx="0" ixy="0" ixz="0" iyy="0" iyz="0" izz="0"/>
    </inertial>
    <visual>
      <origin rpy="0 0 0" xyz="0 0 0"/>
      <geometry>
        <box size="0.05 0.05 1.8"/>
      </geometry>
       <material name="Brown"/>
    </visual>
    <collision>
      <origin rpy="0 0 0" xyz="0 0 0"/>
      <geometry>
       <box size="0.05 0.05 1.8"/>
      </geometry>
    </collision>
  </link>

  <!-- HUSKY-MORPH JOINT -->
  <joint name="morph_to_husky" type="fixed">
    <origin rpy="0 0 -1.57" xyz="0 0 1."/>
    <parent link="platform_link"/>
    <child link="spine"/>
  </joint>

  <link name="arm1">
    <inertial>
      <origin rpy="0 0 0" xyz="0 0 0"/>
       <mass value=".01"/>
       <inertia ixx="0" ixy="0" ixz="0" iyy="0" iyz="0" izz="0"/>
    </inertial>
    <visual>
      <origin rpy="0 1.57 0" xyz="0.15 0 -0.5"/>
      <geometry>
        <box size="0.075 0.075 0.3"/>
      </geometry>
       <material name="black">
        <color rgba="0.01 0.01 0.01 1"/>
      </material>
    </visual>
    <collision>
      <origin rpy="0 1.57 0" xyz="0.15 0 -0.5"/>
      <geometry>
       <box size="0.05 0.05 0.3"/>
      </geometry>
    </collision>
  </link>

  <joint name="spine_to_arm1" type="prismatic">
    <parent link="spine"/>
    <child link="arm1"/>
    <origin rpy="0 0 0" xyz="0 0 0"/>
    <axis xyz="0 0 1"/>
    <limit lower="0.0" upper="1.3" effort="10" velocity="0.25"/>
  </joint>

  <link name="head">
    <inertial>
      <origin rpy="0 0 0" xyz="0 0 0"/>
       <mass value=".01"/>
       <inertia ixx="0" ixy="0" ixz="0" iyy="0" iyz="0" izz="0"/>
    </inertial>
    <visual>
      <origin rpy="0 1.57 0" xyz="0.04 0 0.9"/>
      <geometry>
        <box size="0.05 0.05 0.15"/>
      </geometry>
       <material name="black">
        <color rgba="0.01 0.01 0.01 1"/>
      </material>
    </visual>
    <collision>
      <origin rpy="0 1.57 0" xyz="0.04 0 0.9"/>
      <geometry>
       <box size="0.05 0.05 0.15"/>
      </geometry>
    </collision>
  </link>

  <joint name="spine_to_head" type="fixed">
    <parent link="spine"/>
    <child link="head"/>
  </joint>


  <link name="arm2">
    <inertial>
      <origin rpy="0 0 0" xyz="0 0 0"/>
       <mass value=".01"/>
       <inertia ixx="0" ixy="0" ixz="0" iyy="0" iyz="0" izz="0"/>
    </inertial>
    <visual>
      <origin rpy="0 1.57 0" xyz="0.15 0 -0.5"/>
      <geometry>
        <box size="0.07 0.07 0.3"/>
      </geometry>
       <material name="grey1">
        <color rgba="0.23 0.22 0.21 1"/>
        </material>
    </visual>
    <collision>
      <origin rpy="0 1.57 0" xyz="0.15 0 -0.5"/>
      <geometry>
       <box size="0.07 0.07 0.3"/>
      </geometry>
    </collision>
  </link>

  <joint name="arm1_to_arm2" type="prismatic">
    <parent link="arm1"/>
    <child link="arm2"/>
    <origin rpy="0 0 0" xyz="0 0 0"/>
    <axis xyz="1 0 0"/>
    <limit lower="0.0" upper="0.25" effort="3000" velocity="100"/>
  </joint>

  <link name="arm3">
    <inertial>
      <origin rpy="0 0 0" xyz="0 0 0"/>
       <mass value=".01"/>
       <inertia ixx="0" ixy="0" ixz="0" iyy="0" iyz="0" izz="0"/>
    </inertial>
    <visual>
      <origin rpy="0 1.57 0" xyz="0.15 0 -0.5"/>
      <geometry>
        <box size="0.06 0.06 0.3"/>
      </geometry>
       <material name="grey2">
        <color rgba="0.32 0.31 0.31 1"/>
      </material>
    </visual>
    <collision>
      <origin rpy="0 1.57 0" xyz="0.15 0 -0.5"/>
      <geometry>
       <box size="0.06 0.06 0.3"/>
      </geometry>
    </collision>
  </link>

  <joint name="arm2_to_arm3" type="prismatic">
    <parent link="arm2"/>
    <child link="arm3"/>
    <origin rpy="0 0 0" xyz="0 0 0"/>
    <axis xyz="1 0 0"/>
    <limit lower="0.0" upper="0.25" effort="3000" velocity="100"/>
  </joint>

  <link name="arm4">
    <inertial>
      <origin rpy="0 0 0" xyz="0 0 0"/>
       <mass value=".01"/>
       <inertia ixx="0" ixy="0" ixz="0" iyy="0" iyz="0" izz="0"/>
    </inertial>
    <visual>
      <origin rpy="0 1.57 0" xyz="0.15 0 -0.5"/>
      <geometry>
        <box size="0.05 0.05 0.3"/>
      </geometry>
       <material name="grey3">
        <color rgba="0.49 0.48 0.48 1"/>
      </material>
    </visual>
    <collision>
      <origin rpy="0 1.57 0" xyz="0.15 0 -0.5"/>
      <geometry>
       <box size="0.05 0.05 0.3"/>
      </geometry>
    </collision>
  </link>

  <joint name="arm3_to_arm4" type="prismatic">
    <parent link="arm3"/>
    <child link="arm4"/>
    <origin rpy="0 0 0" xyz="0 0 0"/>
    <axis xyz="1 0 0"/>
    <limit lower="0.0" upper="0.25" effort="3000" velocity="100"/>
  </joint>

  <link name="arm5">
    <inertial>
      <origin rpy="0 0 0" xyz="0 0 0"/>
       <mass value=".01"/>
       <inertia ixx="0" ixy="0" ixz="0" iyy="0" iyz="0" izz="0"/>
    </inertial>
    <visual>
      <origin rpy="0 1.57 0" xyz="0.15 0 -0.5"/>
      <geometry>
        <box size="0.04 0.04 0.3"/>
      </geometry>
       <material name="grey4">
        <color rgba="0.74 0.73 0.73 1"/>
      </material>
    </visual>
    <collision>
      <origin rpy="0 1.57 0" xyz="0.15 0 -0.5"/>
      <geometry>
       <box size="0.04 0.04 0.3"/>
      </geometry>
    </collision>
  </link>

  <joint name="arm4_to_arm5" type="prismatic">
    <parent link="arm4"/>
    <child link="arm5"/>
    <origin rpy="0 0 0" xyz="0 0 0"/>
    <axis xyz="1 0 0"/>
    <limit lower="0.0" upper="0.25" effort="3000" velocity="100"/>
  </joint>

  <link name="wrist">
    <inertial>
      <origin rpy="0 0 0" xyz="0 0 0.02"/>
       <mass value=".01"/>
       <inertia ixx="0" ixy="0" ixz="0" iyy="0" iyz="0" izz="0"/>
    </inertial>
    <visual>
      <origin rpy="0 0 0" xyz="0 0 0"/>

      <geometry>
        <box size="0.04 0.04 0.04"/>
      </geometry>
       <material name="red">
        <color rgba="1 0 0 1"/>
      </material>
    </visual>
    <collision>
      <origin rpy="0 0 0" xyz="0 0 0"/>
      <geometry>
       <box size="0.07 0.07 0.07"/>
      </geometry>
    </collision>
  </link>

  <joint name="arm5_to_wrist" type="fixed">
    <parent link="arm5"/>
    <child link="wrist"/>
    <origin rpy="0 0 0" xyz="0.28 0 -0.54"/>
    <safety_controller k_position="100.0" k_velocity="40.0" soft_lower_limit="-2.8973" soft_upper_limit="2.8973"/>
    <axis xyz="0 0 1"/>
    <limit lower="-3.14" upper="3.14" effort="12000" velocity="2.61"/>
  </joint>

   <link name="hook">
    <inertial>
      <origin rpy="0 0 0" xyz="0 0 0"/>
       <mass value=".01"/>
       <inertia ixx="0" ixy="0" ixz="0" iyy="0" iyz="0" izz="0"/>
    </inertial>
    <visual>
      <origin rpy="0 0 0" xyz="0. 0 0"/>
      <geometry>
        <mesh filename="hook.stl" scale="1 1 1"/>
      </geometry>
       <material name="grey3"/>
    </visual>
    <collision>
      <origin rpy="0 0 0" xyz="0. 0 0"/>
      <geometry>
       <mesh filename="hook.stl" scale="1 1 1"/>
      </geometry>
    </collision>
  </link>




  <link name="gripper_base">
    <inertial>
      <origin rpy="0 0 0" xyz="0 0 0"/>
       <mass value=".01"/>
       <inertia ixx="0" ixy="0" ixz="0" iyy="0" iyz="0" izz="0"/>
    </inertial>
    <visual>
      <origin rpy="0 0 0" xyz="0. 0 0"/>
      <geometry>
        <box size="0.01 0.2 0.03"/>
      </geometry>
       <material name="grey3"/>
    </visual>
    <collision>
      <origin rpy="0 0 0" xyz="0. 0 0"/>
      <geometry>
       <box size="0.01 0.2 0.03"/>
      </geometry>
    </collision>
  </link>

  <joint name="wrist_to_gripper_base" type="fixed">
    <parent link="wrist"/>
    <child link="gripper_base"/>
    <origin rpy="0 -0 0" xyz="0.02 0 -0.01"/>
    <axis xyz="1 0 0"/>
    <limit lower="-3.14" upper="3.14" effort="300" velocity="10"/>
  </joint>

<link name="left_gripper">
    <inertial>
      <origin rpy="0 0 0" xyz="0 0 0"/>
       <mass value=".01"/>
       <inertia ixx="0" ixy="0" ixz="0" iyy="0" iyz="0" izz="0"/>
    </inertial>
    <visual>
      <origin rpy="0 0 0" xyz="0. 0 0"/>
      <geometry>
        <mesh filename="left_gripper.stl" scale="1 1 1"/>
      </geometry>
       <material name="Purple"/>
    </visual>
    <collision>
      <origin rpy="0 0 0" xyz="0. 0 0"/>
      <geometry>
       <mesh filename="left_gripper.stl" scale="1 1 1"/>
      </geometry>
    </collision>
  </link>

  <joint name="gripper_base_to_left_gripper" type="prismatic">
    <parent link="gripper_base"/>
    <child link="left_gripper"/>
    <origin rpy="0. 0 -1.57" xyz="0.062 0.06 -0.011"/>
    <axis xyz="1 0 0"/>
    <limit lower="0.0" upper="0.06" effort="300" velocity="10"/>
  </joint>

<link name="right_gripper">
    <inertial>
      <origin rpy="0 0 0" xyz="0 0 0"/>
       <mass value=".01"/>
       <inertia ixx="0" ixy="0" ixz="0" iyy="0" iyz="0" izz="0"/>
    </inertial>
    <visual>
       <origin rpy="0 0 0" xyz="0. 0 0"/>
      <geometry>
        <mesh filename="right_gripper.stl" scale="1 1 1"/>
      </geometry>
       <material name="Purple"/>
    </visual>
    <collision>
       <origin rpy="0 0 0" xyz="0. 0 0"/>
      <geometry>
       <mesh filename="right_gripper.stl" scale="1 1 1"/>
      </geometry>
    </collision>
  </link>

  <joint name="gripper_base_to_right_gripper" type="prismatic">
    <parent link="gripper_base"/>
    <child link="right_gripper"/>
    <origin rpy="0. 0 -1.57" xyz="0.062 -0.06 -0.011"/>
    <axis xyz="1 0 0"/>
    <limit lower="-0.06" upper="0.0" effort="300" velocity="10"/>
  </joint>

  <joint name="hook_to_wrist" type="fixed">
    <parent link="wrist"/>
    <child link="hook"/>
    <origin rpy="1.57 -0 3.14" xyz="-0.06 0 -0.01"/>
  </joint>

</robot>

