<?xml version="0.0" ?>
<robot name="morpheus">
  <link name="spine">
    <inertial>
      <origin rpy="0 0 0" xyz="0 0 0"/>
       <mass value=".01"/>
       <inertia ixx="0" ixy="0" ixz="0" iyy="0" iyz="0" izz="0"/>
    </inertial>
    <visual>
      <origin rpy="0 0 0" xyz="0 0 0"/>
      <geometry>
				<box size="0.05 0.05 1.8"/>
      </geometry>
       <material name="black">
        <color rgba="0.01 0.01 0.01 1"/>
      </material>
    </visual>
    <collision>
      <origin rpy="0 0 0" xyz="0 0 0"/>
      <geometry>
	 	   <box size="0.05 0.05 1.8"/>
      </geometry>
    </collision>
  </link>

  <link name="arm1">
    <inertial>
      <origin rpy="0 0 0" xyz="0 0 0"/>
       <mass value=".01"/>
       <inertia ixx="0" ixy="0" ixz="0" iyy="0" iyz="0" izz="0"/>
    </inertial>
    <visual>
      <origin rpy="0 1.57 0" xyz="0.15 0 -0.5"/>
      <geometry>
        <box size="0.05 0.05 0.3"/>
      </geometry>
       <material name="black">
        <color rgba="0.01 0.01 0.01 1"/>
      </material>
    </visual>
    <collision>
      <origin rpy="0 1.57 0" xyz="0.15 0 -0.5"/>
      <geometry>
       <box size="0.05 0.05 0.3"/>
      </geometry>
    </collision>
  </link>

  <joint name="spine_to_arm1" type="prismatic">
    <parent link="spine"/>
    <child link="arm1"/>
    <origin rpy="0 0 0" xyz="0 0 0"/>
    <axis xyz="0 0 1"/>
    <limit lower="0.0" upper="1.3" effort="10" velocity="0.25"/>
  </joint>

  <link name="head">
    <inertial>
      <origin rpy="0 0 0" xyz="0 0 0"/>
       <mass value=".01"/>
       <inertia ixx="0" ixy="0" ixz="0" iyy="0" iyz="0" izz="0"/>
    </inertial>
    <visual>
      <origin rpy="0 1.57 0" xyz="0.04 0 0.9"/>
      <geometry>
        <box size="0.05 0.05 0.15"/>
      </geometry>
       <material name="black">
        <color rgba="0.01 0.01 0.01 1"/>
      </material>
    </visual>
    <collision>
      <origin rpy="0 1.57 0" xyz="0.04 0 0.9"/>
      <geometry>
       <box size="0.05 0.05 0.15"/>
      </geometry>
    </collision>
  </link>

  <joint name="spine_to_head" type="fixed">
    <parent link="spine"/>
    <child link="head"/>
  </joint>


  <link name="arm2">
    <inertial>
      <origin rpy="0 0 0" xyz="0 0 0"/>
       <mass value=".01"/>
       <inertia ixx="0" ixy="0" ixz="0" iyy="0" iyz="0" izz="0"/>
    </inertial>
    <visual>
      <origin rpy="0 1.57 0" xyz="0.15 0 -0.5"/>
      <geometry>
        <box size="0.05 0.05 0.3"/>
      </geometry>
       <material name="grey1">
        <color rgba="0.23 0.22 0.21 1"/>
        </material>
    </visual>
    <collision>
      <origin rpy="0 1.57 0" xyz="0.15 0 -0.5"/>
      <geometry>
       <box size="0.05 0.05 0.3"/>
      </geometry>
    </collision>
  </link>

  <joint name="arm1_to_arm2" type="prismatic">
    <parent link="arm1"/>
    <child link="arm2"/>
    <origin rpy="0 0 0" xyz="0 0 0"/>
    <axis xyz="1 0 0"/>
    <limit lower="0.0" upper="0.25" effort="10" velocity="0.25"/>
  </joint>

  <link name="arm3">
    <inertial>
      <origin rpy="0 0 0" xyz="0 0 0"/>
       <mass value=".01"/>
       <inertia ixx="0" ixy="0" ixz="0" iyy="0" iyz="0" izz="0"/>
    </inertial>
    <visual>
      <origin rpy="0 1.57 0" xyz="0.15 0 -0.5"/>
      <geometry>
        <box size="0.05 0.05 0.3"/>
      </geometry>
       <material name="grey2">
        <color rgba="0.32 0.31 0.31 1"/>
      </material>
    </visual>
    <collision>
      <origin rpy="0 1.57 0" xyz="0.15 0 -0.5"/>
      <geometry>
       <box size="0.05 0.05 0.3"/>
      </geometry>
    </collision>
  </link>

  <joint name="arm2_to_arm3" type="prismatic">
    <parent link="arm2"/>
    <child link="arm3"/>
    <origin rpy="0 0 0" xyz="0 0 0"/>
    <axis xyz="1 0 0"/>
    <limit lower="0.0" upper="0.25" effort="10" velocity="0.25"/>
  </joint>

  <link name="arm4">
    <inertial>
      <origin rpy="0 0 0" xyz="0 0 0"/>
       <mass value=".01"/>
       <inertia ixx="0" ixy="0" ixz="0" iyy="0" iyz="0" izz="0"/>
    </inertial>
    <visual>
      <origin rpy="0 1.57 0" xyz="0.15 0 -0.5"/>
      <geometry>
        <box size="0.05 0.05 0.3"/>
      </geometry>
       <material name="grey3">
        <color rgba="0.49 0.48 0.48 1"/>
      </material>
    </visual>
    <collision>
      <origin rpy="0 1.57 0" xyz="0.15 0 -0.5"/>
      <geometry>
       <box size="0.05 0.05 0.3"/>
      </geometry>
    </collision>
  </link>

  <joint name="arm3_to_arm4" type="prismatic">
    <parent link="arm3"/>
    <child link="arm4"/>
    <origin rpy="0 0 0" xyz="0 0 0"/>
    <axis xyz="1 0 0"/>
    <limit lower="0.0" upper="0.25" effort="10" velocity="0.25"/>
  </joint>

  <link name="arm5">
    <inertial>
      <origin rpy="0 0 0" xyz="0 0 0"/>
       <mass value=".01"/>
       <inertia ixx="0" ixy="0" ixz="0" iyy="0" iyz="0" izz="0"/>
    </inertial>
    <visual>
      <origin rpy="0 1.57 0" xyz="0.15 0 -0.5"/>
      <geometry>
        <box size="0.05 0.05 0.3"/>
      </geometry>
       <material name="grey3">
        <color rgba="0.74 0.73 0.73 1"/>
      </material>
    </visual>
    <collision>
      <origin rpy="0 1.57 0" xyz="0.15 0 -0.5"/>
      <geometry>
       <box size="0.05 0.05 0.3"/>
      </geometry>
    </collision>
  </link>

  <joint name="arm4_to_arm5" type="prismatic">
    <parent link="arm4"/>
    <child link="arm5"/>
    <origin rpy="0 0 0" xyz="0 0 0"/>
    <axis xyz="1 0 0"/>
    <limit lower="0.0" upper="0.25" effort="10" velocity="0.25"/>
  </joint>

</robot>

